<?xml version="1.0"?>
<robot name="mmm" xmlns:xacro="http://www.ros.org/wiki/xacro">
  <xacro:property name="PI" value="3.141592"/>
  <!-- Joints Control in Gazebo -->
  <gazebo>
    <plugin name="gazebo_ros_control" filename="libgazebo_ros_control.so"/>
  </gazebo>

  <!-- macro to generate a link model -->
  <!-- reads STL at mmm_description/meshes, and positions it at x,y,z -->
  <xacro:macro name="create_link" params="index">
    <link name="link${index}">
      <visual>
        <geometry>
          <!-- the STL is exported from Fusion 360 in millimeters, while URDF expects it in meters.
        Therefore, scaling is required. -->
          <mesh scale="0.001 0.001 0.001" filename="package://mmm_description/meshes/link${index}.stl"/>
        </geometry>
        <material name="gray"/>
      </visual>

      <collision>
      <geometry>
        <!-- the STL is exported from Fusion 360 in millimeters, while URDF expects it in meters.
      Therefore, scaling is required. -->
        <mesh scale="0.001 0.001 0.001" filename="package://mmm_description/meshes/Slink${index}.stl"/>
      </geometry>
      </collision>
<!--
      <inertial>

      </inertial> -->
    </link>
  </xacro:macro>

  <!-- creates a link between link {index-1} and {index} -->
  <!-- input distances in millimeters. -->
  <xacro:macro name="create_joint" params="index x:=0 y:=0 z:=0 axis angle">
    <joint name="link${index-1}_link${index}_joint" type="revolute">
      <parent link="link${index-1}"/>
      <child link="link${index}"/>
      <origin xyz="${x/1000} ${y/1000} ${z/1000}"/>
      <axis xyz="${axis}"/>
      <limit
        effort="40.0"
        velocity="1.0"
        lower="${-angle*PI/180}"
        upper="${angle*PI/180}"/>
    </joint>
  </xacro:macro>


  <!-- Materials -->
  <material name="brown">
    <color rgba="0.87 0.72 0.53 1.00"/>
  </material>

  <material name="gray">
    <color rgba="0.90 0.90 0.90 1.00"/>
  </material>

  <!-- World frame (for Gazebo) -->
  <link name="world"/>

  <!-- Base fixed to world frame -->
  <joint name="world_base_joint" type="fixed">
    <parent link="world"/>
    <child link="base"/>
  </joint>

  <link name="base">
    <visual>
      <origin xyz="0 0 0" rpy="0 0 0"/>
      <geometry>

        <!-- the STL is exported from Fusion 360 in millimeters, while URDF expects it in meters.
      Therefore, scaling is required. -->
        <mesh scale="0.001 0.001 0.001" filename="package://mmm_description/meshes/base.stl"/>
      </geometry>
      <material name="brown"/>
    </visual>

    <collision>
      <geometry>

        <!-- the STL is exported from Fusion 360 in millimeters, while URDF expects it in meters.
      Therefore, scaling is required. -->
        <mesh scale="0.001 0.001 0.001" filename="package://mmm_description/meshes/Sbase.stl"/>
      </geometry>
    </collision>

    <!-- <inertial>
    </inertial> -->
  </link>

  <joint name="base_link0_joint" type="fixed">
    <parent link="base"/>
    <child link="link0"/>
    <origin xyz="${-30.2/1000} ${0/1000} ${6.9/1000}"/>
  </joint>
  <xacro:create_link index="0"/>


  <xacro:create_joint index="1" z="31" axis="0 0 1" angle="120"/>
  <xacro:create_link index="1"/>


  <xacro:create_joint index="2" y="15.46" z="20.25" axis="0 1 0" angle="60"/>
  <xacro:create_link index="2"/>

  <xacro:create_joint index="3" z="48" axis="0 1 0" angle="60"/>
  <xacro:create_link index="3"/>

  <xacro:create_joint index="4" x="13.72" y="-15.5" z="53.22" axis="1 0 0" angle="90"/>
  <xacro:create_link index="4"/>

  <xacro:create_joint index="5" x="-15.8" y="-15.9" z="40" axis="0 1 0" angle="90"/>
  <xacro:create_link index="5"/>

  <xacro:create_joint index="6" y="13.9" z="69.5" axis="0 0 1" angle="135"/>
  <xacro:create_link index="6"/>

  <joint name="link6_gripper_frame_joint" type="fixed">
    <parent link="link6" />
    <child link="gripper_frame"/>
    <origin xyz="0 0 ${50/1000}"/>
  </joint>
  <link name="gripper_frame">
  </link>

  <xacro:create_joint index="7" y="-13.9" z="23.5" axis="0 1 0" angle="20">
  </xacro:create_joint>
  <xacro:create_link index="7"/>



  <joint name="link6_link7b_joint" type="revolute">
    <parent link="link6"/>
    <child link="link7b"/>
    <origin xyz="${-20.97/1000} ${13.04/1000} ${34/1000}" rpy="0 0 ${PI}"/>
    <axis xyz="0 1 0"/>
    <limit
      effort="40.0"
      velocity="1.0"
      lower="${-PI}"
      upper="${PI}"/>
    <mimic joint="link6_link7_joint" offset="${-PI*50/180}"/>
  </joint>
  <link name="link7b">
    <visual>
      <geometry>
        <!-- the STL is exported from Fusion 360 in millimeters, while URDF expects it in meters.
      Therefore, scaling is required. -->
        <mesh scale="0.001 0.001 0.001" filename="package://mmm_description/meshes/link7.stl"/>
      </geometry>
      <material name="gray"/>
    </visual>

    <collision>
      <geometry>
        <!-- the STL is exported from Fusion 360 in millimeters, while URDF expects it in meters.
      Therefore, scaling is required. -->
        <mesh scale="0.001 0.001 0.001" filename="package://mmm_description/meshes/Slink7.stl"/>
      </geometry>

    </collision>

    <!-- <inertial>

    </inertial> -->
  </link>

  <joint name="link7b_camera_joint" type="fixed">
    <parent link="link7b"/>
    <child link="raspicam"/>
    <origin xyz="${21/1000} ${14.93/1000} ${13.9/1000}" rpy="0 ${115*PI/180} 0"/>
  </joint>

  <link name="raspicam">
    <visual>
      <origin xyz="0 0 0" rpy="0 ${-PI/2} 0"/>
      <geometry>
        <!-- the STL is exported from Fusion 360 in millimeters, while URDF expects it in meters.
      Therefore, scaling is required. -->
        <mesh scale="0.001 0.001 0.001" filename="package://mmm_description/meshes/camera.stl"/>
      </geometry>
      <material name="brown"/>
    </visual>
    <!--
    <collision>
    </collision>

    <inertial>
    </inertial> -->
  </link>


</robot>
